## [创建自定义错误](https://www.digitalocean.com/community/tutorials/creating-custom-errors-in-go)

由 **Gopher Guides** 编写，[@JialeDai](https://github.com/daijiale) 译

Go标准库提供了两种创建错误异常的方式，`errors.New`和`fmt.Errorf`。当我们需要向用户传达更多复杂场景下的异常信息，亦或是为了方便后期自己调试，以上这两种方式并不适合去捕获和反馈程序究竟发生了什么问题。为了传达出更详尽的错误信息和使其更具实用性，我们可以重新声明标准库的`error`类型接口，语法如下：

```go
type error interface { 
    Error() string
}
```

[builtin](https://golang.org/pkg/builtin/)包使用一个返回字符串错误信息的`Error()`方法来定义`error`接口。通过重写这个方法，我们可以自定义异常返回的数据类型。

让我们试着看一个这样的例子：

```golang

package main

import (
    "fmt"
    "os"
)

type MyError struct{}

func (m *MyError) Error() string {
    return "boom"
}

func sayHello() (string, error) {
    return "", &MyError{}
}

func main() {
    s, err := sayHello()
    if err != nil {
        fmt.Println("unexpected error: err:", err)
        os.Exit(1)
    }
    fmt.Println("The string:", s)
}

```
我们可以看到如下输出结果：

```
unexpected error: err: boom
exit status 1
```

我们创建了一个新的空机构体：`MyError`，并且为它定义了`Error()`方法。`Error()`方法返回了字符串`boom`。

在`main()`方法中，我们调用了返回空字符串和`MyError`的`sayHello`方法。由于`sayHello`将始终返回错误，因此程序将始终执行`main()`中if语句主体内的`fmt.Println`。之后，我们将使用`fmt.Println`打印出`unexpected error:`前缀，并将`MyError`替换错误变量。

请注意，由于`fmt`包能够自动检测到这是`error`的实现，因此我们不必直接调用`Error()`，就可以获取到字符串`boom`，并将其与前缀字符串`unexpected error:``连接起来。

#### 通过自定义异常收集详细错误信息

有时，通过自定义来捕获详细错误信息的方式是最佳的。例如，假设我们需要捕获HTTP请求产生的错误状态码，需要运行以下程序，查看错误的实现，该错误的自定义实现使我们能够清晰地捕获该信息：

```golang

package main

import (
    "errors"
    "fmt"
    "os"
)

type RequestError struct {
    StatusCode int
    Err error
}

func (r *RequestError) Error() string {
    return fmt.Sprintf("status %d: err %v", r.StatusCode, r.Err)
}

func doRequest() error {
    return &RequestError{
        StatusCode: 503,
        Err:        errors.New("unavailable"),
    }
}

func main() {
    err := doRequest()
    if err != nil {
        fmt.Println(err)
        os.Exit(1)
    }
    fmt.Println("success!")
}

```
我们看到下列输出：

```
status 503: err unavailable
exit status 1

```

在此示例中，我们创建了一个`RequestError`新实例，同时定义了状态码，并用基础库`errors.New`方法定义了一个错误。我们之后使用`fmt.Println`打印出了这个自定义异常。在通过`RequestError`自定义的Error()方法中，我们使用`fmt.Sprintf`函数来构造错误信息。


#### 类型的断言和自定义错误

`error`接口仅对外暴露一种方法，但是我们需要访问错误实现的其他方法才可能正常处理错误。例如，我们可能有一些错误的自定义实现是临时性的，并通过`Temporary()`方法来判断是否应当重新适配。

Go语言中的接口是一种内置的类型，它定义了一组方法的签名，因此我们必须使用类型断言来判断后续的程序展现逻辑。

下面的示例将前面显示的`RequestError`升级为新增了一个`Temporary（）`方法，该方法将指示调用方是否应该重试该请求：

```golang
package main

import (
    "errors"
    "fmt"
    "net/http"
    "os"
)

type RequestError struct {
    StatusCode int

    Err error
}

func (r *RequestError) Error() string {
    return r.Err.Error()
}

func (r *RequestError) Temporary() bool {
    return r.StatusCode == http.StatusServiceUnavailable // 503
}

func doRequest() error {
    return &RequestError{
        StatusCode: 503,
        Err:        errors.New("unavailable"),
    }
}

func main() {
    err := doRequest()
    if err != nil {
        fmt.Println(err)
        re, ok := err.(*RequestError)
        if ok {
            if re.Temporary() {
                fmt.Println("This request can be tried again")
            } else {
                fmt.Println("This request cannot be tried again")
            }
        }
        os.Exit(1)
    }

    fmt.Println("success!")
}

```

我们将会看到如下的输出：

```
unavailable
This request can be tried again
exit status 1

```
在`main()`方法里，我们执行了一个返回值为`error`接口的`doRequest()`方法。我们首先打印了通过`Error()`方法返回的错误信息。接下来，我们尝试使用类型断言`re, ok := err.(*RequestError)`来判断接口是否保存了`RequestError`类型。如果断言返回值为成功，我们将使用`Temporary()`方法来判断是否这个错误时一个`符合Temporary()`规则的异常。由于`StatusCode`在`doRequest`中被赋值为503，与`http.StatusServiceUnavailable`值相等，因此最后程序输出`This request can be tried again`。在实际使用中，我们常常会用来再次发起一个请求（二次重试）而非打印一条信息。


#### 包装错误

通常，错误是由程序外部的依赖环境产生的，例如：数据库，网络连接，中间件等。这些依赖方提供的错误消息无法帮助任何人找到错误的根源。在错误消息的开头用额外的信息包装错误将为成功调试提供一些必要的上下文参考。 以下示例演示了如何将一些上下文信息附加外部依赖所产生的错误中：

```golang

package main

import (
    "errors"
    "fmt"
)

type WrappedError struct {
    Context string
    Err     error
}

func (w *WrappedError) Error() string {
    return fmt.Sprintf("%s: %v", w.Context, w.Err)
}

func Wrap(err error, info string) *WrappedError {
    return &WrappedError{
        Context: info,
        Err:     err,
    }
}

func main() {
    err := errors.New("boom!")
    err = Wrap(err, "main")

    fmt.Println(err)
}

```
程序将显示如下输出：

```golang
main:boom
```
`WrappedError`是具有两个字段类型的结构体：一个包含上下文信息的`string`类型的，一个包含更多信息的`error`类型。调用`Error（）`方法时，我们再次使用fmt.Sprintf打印拼接错误消息。

 在`main（）`中，我们使用`errors.New`创建错误，然后使用定义的`Wrap`函数包装该错误。这使我们可以指示此错误是在`main`中生成的。另外，由于`WrappedError`本身也是一个错误，我们可以包装其他`WrappedError`，这将使我们能够看到错误发生的整条链路信息，帮助我们跟踪追溯错误的来源。在标准库的一点帮助下，我们甚至可以在错误中嵌入完整的堆栈跟踪。


### 小结

由于错误接口是一种将具有共性的方法定义在一起的数据类型，我们基于它看到了在不同情况下提供不同错误类型的灵活性。其不仅可以传达多个信息（作为错误的一部分），也可以实现[递归回退](https://en.wikipedia.org/wiki/Exponential_backoff)的场景。虽然Go的错误处理机制从表面上看似乎很简单，但是我们可以使用这些自定义错误来处理更复杂的情况，从而实现满足各种场景下的处理方式。 Go还有另一种机制来传达异常行为，即：恐慌（panics）。在下一篇文章中，我们将研究什么是恐慌，以及如何处理它们。
